# 错误处理与测试

之前番外篇学过了，panic，但确实是没玩明白。

这些会讲到的错误方法，都包含条件的判断，为什么不直接print打出来，我的猜想是，要记录到log里面。

Go 检查和报告错误条件的惯有方式：

-   产生错误的函数会返回两个变量，一个值和一个错误码；如果后者是 nil 就是成功，非 nil 就是发生了错误。
    
-   为了防止发生错误时正在执行的函数（如果有必要的话甚至会是整个程序）被中止，在调用函数后必须检查错误。

一般不会终止，而是返回错误代码，要是终止了，就是很严重的问题。

当程序处于错误状态时可以用 `os.Exit(1)` 来中止运行。

按照惯例，错误通常是最后一个返回值并且是 `error` 类型，它是一个内建的接口。
```go
type error interface { 
	Error() string 
	}
```

## 需要一个新的错误类型，都可以用 `errors.New()`

下面例子的核心思想么，就是用errors.New()设置一个自定义的报错语句，同时设定一个满足error interface（标准错误接口）的struct，虽然struct里有两个元素，但是自己创造方法，让这两个元素都作用在了返回值为string的方法Error()中，struct实现了interface里的所有方法（虽然此处只有一个），所以就达成了鸭子类型。
```go
package main

import (
	"errors"
	"fmt"
)

func f1(arg int) (int, error) {
	if arg == 42 {
		//errors.New 使用给定的错误信息构造一个基本的 error 值。
		//对New的每次调用都会返回一个不同的错误值，即使文本是相同的。
		return -1, errors.New("can't work with 42")
	}
	return arg + 3, nil
}

//你还可以通过实现 Error() 方法来自定义 error 类型。
//(实现接口内的所有方法就算是实现了这个接口。)
//这里使用自定义错误类型来表示上面例子中的参数错误。
type argError struct {
	arg  int
	prob string
}

//在这个例子中，我们使用 &argError 语法来建立一个新的结构体，
//并提供了 arg 和 prob 两个字段的值。
//定义error interface内的Error() string方法
func (e *argError) Error() string {
	return fmt.Sprintf("%d - %s", e.arg, e.prob)
}

func f2(arg int) (int, error) {
	if arg == 42 {
		return -1, &argError{arg, "can't work with it"} //修改结构体的原始值。
	}
	return arg + 3, nil
}

//下面的两个循环测试了每一个会返回错误的函数。
//注意，在 if 的同一行进行错误检查，是 Go 代码中的一种常见用法。
func main() {
	for _, i := range []int{7, 42} { //这个是数组内包含7和42这两个数
		if r, e := f1(i); e != nil { //依次历遍的时候，42复合f1的条件，return -1, errors.New("can't work with 42")
			fmt.Println("f1 failed:", e)
		} else {
			fmt.Println("f1 worked:", r)
		}
	}
	for _, i := range []int{7, 42} {
		if r, e := f2(i); e != nil {
			fmt.Println("f2 failed:", e)
		} else {
			fmt.Println("f2 worked:", r)
		}
	}
	//如果你想在程序中使用自定义错误类型的数据， 你需要通过类型断言来得到这个自定义错误类型的实例。
	_, e := f2(42)
	if ae, ok := e.(*argError); ok {
		fmt.Println(ae.arg)
		fmt.Println(ae.prob)
	}
}

/*
f1 worked: 10
f1 failed: can't work with 42
f2 worked: 10
f2 failed: 42 - can't work with it
42
can't work with it
*/

```

##  `fmt.Errorf()`:用信息生成错误对象，返回包含错误参数的字符串


```go
if f < 0 {
	return 0, fmt.Errorf("math: square root of negative number %g", f)
}
```

把f向前格式化到%g中。

## 运行时异常和 panic

panic的出现会抛出一个`runtime.Error`的interface类型的值，

实现这个接口的方法，有个叫做 `RuntimeError()` 的方法。

一般而言，一个鲁棒性高的程序，在go语言无处不在的错误相关的返回值的情况下，报错，也不影响程序接着跑。panic，蓝屏的起源，问题严重的时候就不管鲁棒性了，打出panic，直接GG。

 `panic` 函数制造一个中止程序的运行时错误。
 
 `panic` 接收一个做任意类型的参数，通常是字符串，在程序死亡时被打印出来。运行时负责中止程序并给出调试信息。

例子
```go
package main

import "fmt"

func main() {
	fmt.Println("Starting the program")
	panic("A severe error occurred: stopping the program!")
	fmt.Println("Ending the program")
}
```

输出如下：

```go
Starting the program
panic: A severe error occurred: stopping the program!
panic PC=0x4f3038
runtime.panic+0x99 /go/src/pkg/runtime/proc.c:1032
       runtime.panic(0x442938, 0x4f08e8)
main.main+0xa5 E:/Go/GoBoek/code examples/chapter 13/panic.go:8
       main.main()
runtime.mainstart+0xf 386/asm.s:84
       runtime.mainstart()
runtime.goexit /go/src/pkg/runtime/proc.c:148
       runtime.goexit()
---- Error run E:/Go/GoBoek/code examples/chapter 13/panic.exe with code Crashed
---- Program exited with code -1073741783
```

一个检查程序是否被已知用户启动的具体例子：

```go
var user = os.Getenv("USER")

func check() {
	if user == "" {
		panic("Unknown user: no value for $USER")
	}
}
```

可以在导入包的 init() 函数中检查这些。

当发生错误必须中止程序时，`panic` 可以用于错误处理模式,就是与上面提到的函数联用：

```go
if err != nil {
	panic("ERROR occurred:" + err.Error())
}
```

## panic与defer与多层嵌套的函数调用
某一层：panic了，defer会保证执行并把控制权给上一级接收到panic的函数调用者，直到最上层，每层都执行defer，在最上层崩溃的话，在命令行中传给panic的值的报告错误情况。
这个过程被称为，panicking。


不能随意地用 panic 中止程序，必须尽力补救错误让程序能继续执行。

## Recover：从panic中恢复。
`Recover`只能在defer后面用，用于重获控制权，停止 终止进程，恢复正常运行。

用于取得 panic 调用中传递过来的错误值，如果是正常执行，调用 `recover` 会返回 nil，且没有其它效果。

下面例子中
用到了**闭包**：一个函数和对其周围状态（**lexical environment，词法环境**）的引用捆绑在一起（或者说函数被引用包围），这样的组合就是**闭包**（**closure**）。也就是说，闭包让你可以在一个内层函数中访问到其外层函数的作用域。


protect 函数调用函数参数 g 来保护调用者防止从 g 中抛出的运行时 panic，并展示 panic 中的信息：

```go
func protect(g func()) {
	defer func() {
		log.Println("done")
		// Println executes normally even if there is a panic
		if err := recover(); err != nil {
			log.Printf("run time panic: %v", err)
		}
	}()
	log.Println("start")
	g() //   possible runtime-error
}
```

这跟 Java 和 .NET 这样的语言中的 catch 块类似。

默认的 log 对象向标准错误输出中写入并打印每条日志信息的日期和时间

除了 `Println` 和 `Printf` 函数，其它的致命性函数都会在写完日志信息后调用 os.Exit(1)，那些退出函数也是如此。

这是一个展示 panic，defer 和 recover 怎么结合使用的完整例子：

```go
// panic_recover.go
package main

import (
	"fmt"
)

func badcall() {
	panic("justpanic\r\n")
}
func test() {
	fmt.Printf("4\r\n")
	defer func() {
		if re := recover(); re != nil {
			fmt.Printf("recover\r\n")
		}
	}()
	badcall()
	fmt.Printf("1\r\n")

}
func main() {
	fmt.Printf("2\r\n")
	test()
	fmt.Printf("3\r\n")

}

```

输出：

```
2 
4 
recover 
3
```

`defer-panic-recover` 在某种意义上也是一种像 `if`，`for` 这样的控制流机制。

此处的
```go
defer func() {
		if re := recover(); re != nil {
			fmt.Printf("recover\r\n")
		}
	}()
```
还真要放在panic前面，不然就会在编译纠正机制（recover）前先报错，panic之后就不会去接着读代码，然后纠正机制就形同虚设了。

看输出值，panic后面，即使recover了，这个函数剩下的也不会执行了。

Go 标准库中许多地方都用了这个机制，例如，json 包中的解码和 regexp 包中的 Complie 函数。Go 库的原则是即使在包的内部使用了 panic，在它的对外接口（API）中也必须用 recover 处理成返回显式的错误。

## 自定义包中的错误处理  和  panicking

这是所有自定义包实现者应该遵守的最佳实践：

1）在包内部，总是应该从 panic 中 recover：不允许显式的超出包范围的 panic()

2）向包的调用者返回错误值（而不是 panic）。

